2025-05-02 22:49:51 [ERROR] [-] zap_scanner.zap_scanner._run_ajax_spider:1135 - Unexpected error running AJAX Spider: 'ajaxSpider' object has no attribute 'set_option_element_id'
Traceback (most recent call last):
  File "c:\Users\grabowmar\Desktop\ThesisAppsSvelte\z_interface_app\zap_scanner.py", line 1099, in _run_ajax_spider
    self.zap.ajaxSpider.set_option_element_id(None)
    ^^^^^^^^^^^^^^^^^^^^^^^^^^^^^^^^^^^^^^^^^
AttributeError: 'ajaxSpider' object has no attribute 'set_option_element_id'. Did you mean: 'set_option_event_wait'?
2025-05-02 22:50:08 [ERROR] [-] zap.zap.thread.Llama-2.run_scan_thread:910 - Error during background scan Llama-2-1746218959: 'ScanManager' object has no attribute 'get_scan_status'
Traceback (most recent call last):
  File "c:\Users\grabowmar\Desktop\ThesisAppsSvelte\z_interface_app\routes.py", line 864, in run_scan_thread
    current_state = current_scan_manager.get_scan_status(scan_id_thread)
                    ^^^^^^^^^^^^^^^^^^^^^^^^^^^^^^^^^^^^
AttributeError: 'ScanManager' object has no attribute 'get_scan_status'. Did you mean: 'get_scan_details'?
2025-05-02 23:11:27 [ERROR] [-] zap.zap.thread.Llama-2.run_scan_thread:910 - Error during background scan Llama-2-1746219205: 'ScanManager' object has no attribute 'get_scan_status'
Traceback (most recent call last):
  File "c:\Users\grabowmar\Desktop\ThesisAppsSvelte\z_interface_app\routes.py", line 864, in run_scan_thread
    current_state = current_scan_manager.get_scan_status(scan_id_thread)
                    ^^^^^^^^^^^^^^^^^^^^^^^^^^^^^^^^^^^^
AttributeError: 'ScanManager' object has no attribute 'get_scan_status'. Did you mean: 'get_scan_details'?
2025-05-02 23:25:37 [ERROR] [-] zap.zap.thread.Llama-2.run_scan_thread:910 - Error during background scan Llama-2-1746221068: 'ScanManager' object has no attribute 'get_scan_status'
Traceback (most recent call last):
  File "c:\Users\grabowmar\Desktop\ThesisAppsSvelte\z_interface_app\routes.py", line 864, in run_scan_thread
    current_state = current_scan_manager.get_scan_status(scan_id_thread)
                    ^^^^^^^^^^^^^^^^^^^^^^^^^^^^^^^^^^^^
AttributeError: 'ScanManager' object has no attribute 'get_scan_status'. Did you mean: 'get_scan_details'?
2025-05-02 23:46:26 [ERROR] [-] zap_scanner.zap_scanner.generate_affected_code_report:1480 - Error saving report to c:\Users\grabowmar\Desktop\ThesisAppsSvelte\z_interface_app\Llama\app2\.zap_code_report.md: [Errno 2] No such file or directory: 'c:\\Users\\grabowmar\\Desktop\\ThesisAppsSvelte\\z_interface_app\\Llama\\app2\\.zap_code_report.md'
2025-05-02 23:46:26 [ERROR] [-] zap.zap.thread.Llama-2.run_scan_thread:910 - Error during background scan Llama-2-1746221440: 'ScanManager' object has no attribute 'get_scan_status'
Traceback (most recent call last):
  File "c:\Users\grabowmar\Desktop\ThesisAppsSvelte\z_interface_app\routes.py", line 864, in run_scan_thread
    current_state = current_scan_manager.get_scan_status(scan_id_thread)
                    ^^^^^^^^^^^^^^^^^^^^^^^^^^^^^^^^^^^^
AttributeError: 'ScanManager' object has no attribute 'get_scan_status'. Did you mean: 'get_scan_details'?
2025-05-02 23:47:56 [ERROR] [-] batch_analysis.batch_analysis.init_batch_analysis:2744 - Missing required services: frontend_security_analyzer (for frontend_security), backend_security_analyzer (for backend_security), performance_tester (for performance), gpt4all_analyzer (for gpt4all), scan_manager (for zap). Related tasks will fail.
2025-05-02 23:48:12 [ERROR] [-] batch_analysis.batch_analysis.init_batch_analysis:2744 - Missing required services: frontend_security_analyzer (for frontend_security), backend_security_analyzer (for backend_security), performance_tester (for performance), gpt4all_analyzer (for gpt4all), scan_manager (for zap). Related tasks will fail.
2025-05-02 23:48:13 [ERROR] [-] ajax.ajax.index.wrapped:228 - Error encountered in decorated function 'index'
Traceback (most recent call last):
  File "c:\Users\grabowmar\Desktop\ThesisAppsSvelte\z_interface_app\utils.py", line 200, in wrapped
    result = f(*args, **kwargs)
             ^^^^^^^^^^^^^^^^^^
  File "c:\Users\grabowmar\Desktop\ThesisAppsSvelte\z_interface_app\routes.py", line 109, in index
    docker_manager: DockerManager = current_app.config["docker_manager"]
                                    ~~~~~~~~~~~~~~~~~~^^^^^^^^^^^^^^^^^^
KeyError: 'docker_manager'
2025-05-02 23:48:14 [ERROR] [-] ajax.ajax.system_info.wrapped:228 - Error encountered in decorated function 'system_info'
Traceback (most recent call last):
  File "c:\Users\grabowmar\Desktop\ThesisAppsSvelte\z_interface_app\utils.py", line 200, in wrapped
    result = f(*args, **kwargs)
             ^^^^^^^^^^^^^^^^^^
  File "c:\Users\grabowmar\Desktop\ThesisAppsSvelte\z_interface_app\routes.py", line 366, in system_info
    docker_manager: DockerManager = current_app.config["docker_manager"]
                                    ~~~~~~~~~~~~~~~~~~^^^^^^^^^^^^^^^^^^
KeyError: 'docker_manager'
2025-05-02 23:48:21 [ERROR] [-] batch_analysis.batch_analysis.init_batch_analysis:2744 - Missing required services: frontend_security_analyzer (for frontend_security), backend_security_analyzer (for backend_security), performance_tester (for performance), gpt4all_analyzer (for gpt4all), scan_manager (for zap). Related tasks will fail.
2025-05-02 23:48:22 [ERROR] [-] batch_analysis.batch_analysis.init_batch_analysis:2744 - Missing required services: frontend_security_analyzer (for frontend_security), backend_security_analyzer (for backend_security), performance_tester (for performance), gpt4all_analyzer (for gpt4all), scan_manager (for zap). Related tasks will fail.
2025-05-02 23:48:24 [ERROR] [-] ajax.ajax.index.wrapped:228 - Error encountered in decorated function 'index'
Traceback (most recent call last):
  File "c:\Users\grabowmar\Desktop\ThesisAppsSvelte\z_interface_app\utils.py", line 200, in wrapped
    result = f(*args, **kwargs)
             ^^^^^^^^^^^^^^^^^^
  File "c:\Users\grabowmar\Desktop\ThesisAppsSvelte\z_interface_app\routes.py", line 109, in index
    docker_manager: DockerManager = current_app.config["docker_manager"]
                                    ~~~~~~~~~~~~~~~~~~^^^^^^^^^^^^^^^^^^
KeyError: 'docker_manager'
2025-05-02 23:48:25 [ERROR] [-] ajax.ajax.system_info.wrapped:228 - Error encountered in decorated function 'system_info'
Traceback (most recent call last):
  File "c:\Users\grabowmar\Desktop\ThesisAppsSvelte\z_interface_app\utils.py", line 200, in wrapped
    result = f(*args, **kwargs)
             ^^^^^^^^^^^^^^^^^^
  File "c:\Users\grabowmar\Desktop\ThesisAppsSvelte\z_interface_app\routes.py", line 366, in system_info
    docker_manager: DockerManager = current_app.config["docker_manager"]
                                    ~~~~~~~~~~~~~~~~~~^^^^^^^^^^^^^^^^^^
KeyError: 'docker_manager'
2025-05-02 23:49:26 [ERROR] [-] ajax.ajax.system_info.wrapped:228 - Error encountered in decorated function 'system_info'
Traceback (most recent call last):
  File "c:\Users\grabowmar\Desktop\ThesisAppsSvelte\z_interface_app\utils.py", line 200, in wrapped
    result = f(*args, **kwargs)
             ^^^^^^^^^^^^^^^^^^
  File "c:\Users\grabowmar\Desktop\ThesisAppsSvelte\z_interface_app\routes.py", line 366, in system_info
    docker_manager: DockerManager = current_app.config["docker_manager"]
                                    ~~~~~~~~~~~~~~~~~~^^^^^^^^^^^^^^^^^^
KeyError: 'docker_manager'
2025-05-02 23:50:26 [ERROR] [-] ajax.ajax.system_info.wrapped:228 - Error encountered in decorated function 'system_info'
Traceback (most recent call last):
  File "c:\Users\grabowmar\Desktop\ThesisAppsSvelte\z_interface_app\utils.py", line 200, in wrapped
    result = f(*args, **kwargs)
             ^^^^^^^^^^^^^^^^^^
  File "c:\Users\grabowmar\Desktop\ThesisAppsSvelte\z_interface_app\routes.py", line 366, in system_info
    docker_manager: DockerManager = current_app.config["docker_manager"]
                                    ~~~~~~~~~~~~~~~~~~^^^^^^^^^^^^^^^^^^
KeyError: 'docker_manager'
2025-05-02 23:51:26 [ERROR] [-] ajax.ajax.system_info.wrapped:228 - Error encountered in decorated function 'system_info'
Traceback (most recent call last):
  File "c:\Users\grabowmar\Desktop\ThesisAppsSvelte\z_interface_app\utils.py", line 200, in wrapped
    result = f(*args, **kwargs)
             ^^^^^^^^^^^^^^^^^^
  File "c:\Users\grabowmar\Desktop\ThesisAppsSvelte\z_interface_app\routes.py", line 366, in system_info
    docker_manager: DockerManager = current_app.config["docker_manager"]
                                    ~~~~~~~~~~~~~~~~~~^^^^^^^^^^^^^^^^^^
KeyError: 'docker_manager'
2025-05-02 23:52:26 [ERROR] [-] ajax.ajax.system_info.wrapped:228 - Error encountered in decorated function 'system_info'
Traceback (most recent call last):
  File "c:\Users\grabowmar\Desktop\ThesisAppsSvelte\z_interface_app\utils.py", line 200, in wrapped
    result = f(*args, **kwargs)
             ^^^^^^^^^^^^^^^^^^
  File "c:\Users\grabowmar\Desktop\ThesisAppsSvelte\z_interface_app\routes.py", line 366, in system_info
    docker_manager: DockerManager = current_app.config["docker_manager"]
                                    ~~~~~~~~~~~~~~~~~~^^^^^^^^^^^^^^^^^^
KeyError: 'docker_manager'
2025-05-02 23:52:28 [ERROR] [-] batch_analysis.batch_analysis.init_batch_analysis:2744 - Missing required services: frontend_security_analyzer (for frontend_security), backend_security_analyzer (for backend_security), performance_tester (for performance), gpt4all_analyzer (for gpt4all), scan_manager (for zap). Related tasks will fail.
2025-05-02 23:59:25 [ERROR] [-] zap_scanner.zap_scanner._run_ajax_spider:1135 - Unexpected error running AJAX Spider: 'ajaxSpider' object has no attribute 'set_option_element_id'
Traceback (most recent call last):
  File "c:\Users\grabowmar\Desktop\ThesisAppsSvelte\z_interface_app\zap_scanner.py", line 1099, in _run_ajax_spider
    self.zap.ajaxSpider.set_option_element_id(None)
    ^^^^^^^^^^^^^^^^^^^^^^^^^^^^^^^^^^^^^^^^^
AttributeError: 'ajaxSpider' object has no attribute 'set_option_element_id'. Did you mean: 'set_option_event_wait'?
2025-05-02 23:59:41 [ERROR] [-] zap.zap.thread.Llama-2.run_scan_thread:910 - Error during background scan Llama-2-1746223132: 'ScanManager' object has no attribute 'get_scan_status'
Traceback (most recent call last):
  File "c:\Users\grabowmar\Desktop\ThesisAppsSvelte\z_interface_app\routes.py", line 864, in run_scan_thread
    current_state = current_scan_manager.get_scan_status(scan_id_thread)
                    ^^^^^^^^^^^^^^^^^^^^^^^^^^^^^^^^^^^^
AttributeError: 'ScanManager' object has no attribute 'get_scan_status'. Did you mean: 'get_scan_details'?
2025-05-03 13:17:57 [ERROR] [-] docker.docker._create_docker_client:124 - Docker client creation or connection failed: Error while fetching server API version: (2, 'CreateFile', 'Nie można odnaleźć określonego pliku.')
Traceback (most recent call last):
  File "C:\Users\grabowmar\Desktop\ThesisAppsSvelte\.venv\Lib\site-packages\docker\api\client.py", line 223, in _retrieve_server_version
    return self.version(api_version=False)["ApiVersion"]
           ^^^^^^^^^^^^^^^^^^^^^^^^^^^^^^^
  File "C:\Users\grabowmar\Desktop\ThesisAppsSvelte\.venv\Lib\site-packages\docker\api\daemon.py", line 181, in version
    return self._result(self._get(url), json=True)
                        ^^^^^^^^^^^^^^
  File "C:\Users\grabowmar\Desktop\ThesisAppsSvelte\.venv\Lib\site-packages\docker\utils\decorators.py", line 44, in inner
    return f(self, *args, **kwargs)
           ^^^^^^^^^^^^^^^^^^^^^^^^
  File "C:\Users\grabowmar\Desktop\ThesisAppsSvelte\.venv\Lib\site-packages\docker\api\client.py", line 246, in _get
    return self.get(url, **self._set_request_timeout(kwargs))
           ^^^^^^^^^^^^^^^^^^^^^^^^^^^^^^^^^^^^^^^^^^^^^^^^^^
  File "C:\Users\grabowmar\Desktop\ThesisAppsSvelte\.venv\Lib\site-packages\requests\sessions.py", line 602, in get
    return self.request("GET", url, **kwargs)
           ^^^^^^^^^^^^^^^^^^^^^^^^^^^^^^^^^^
  File "C:\Users\grabowmar\Desktop\ThesisAppsSvelte\.venv\Lib\site-packages\requests\sessions.py", line 589, in request
    resp = self.send(prep, **send_kwargs)
           ^^^^^^^^^^^^^^^^^^^^^^^^^^^^^^
  File "C:\Users\grabowmar\Desktop\ThesisAppsSvelte\.venv\Lib\site-packages\requests\sessions.py", line 703, in send
    r = adapter.send(request, **kwargs)
        ^^^^^^^^^^^^^^^^^^^^^^^^^^^^^^^
  File "C:\Users\grabowmar\Desktop\ThesisAppsSvelte\.venv\Lib\site-packages\requests\adapters.py", line 667, in send
    resp = conn.urlopen(
           ^^^^^^^^^^^^^
  File "C:\Users\grabowmar\Desktop\ThesisAppsSvelte\.venv\Lib\site-packages\urllib3\connectionpool.py", line 787, in urlopen
    response = self._make_request(
               ^^^^^^^^^^^^^^^^^^^
  File "C:\Users\grabowmar\Desktop\ThesisAppsSvelte\.venv\Lib\site-packages\urllib3\connectionpool.py", line 493, in _make_request
    conn.request(
  File "C:\Users\grabowmar\Desktop\ThesisAppsSvelte\.venv\Lib\site-packages\urllib3\connection.py", line 445, in request
    self.endheaders()
  File "c:\Users\grabowmar\AppData\Local\Programs\Python\Python312\Lib\http\client.py", line 1331, in endheaders
    self._send_output(message_body, encode_chunked=encode_chunked)
  File "c:\Users\grabowmar\AppData\Local\Programs\Python\Python312\Lib\http\client.py", line 1091, in _send_output
    self.send(msg)
  File "c:\Users\grabowmar\AppData\Local\Programs\Python\Python312\Lib\http\client.py", line 1035, in send
    self.connect()
  File "C:\Users\grabowmar\Desktop\ThesisAppsSvelte\.venv\Lib\site-packages\docker\transport\npipeconn.py", line 25, in connect
    sock.connect(self.npipe_path)
  File "C:\Users\grabowmar\Desktop\ThesisAppsSvelte\.venv\Lib\site-packages\docker\transport\npipesocket.py", line 25, in wrapped
    return f(self, *args, **kwargs)
           ^^^^^^^^^^^^^^^^^^^^^^^^
  File "C:\Users\grabowmar\Desktop\ThesisAppsSvelte\.venv\Lib\site-packages\docker\transport\npipesocket.py", line 76, in connect
    raise e
  File "C:\Users\grabowmar\Desktop\ThesisAppsSvelte\.venv\Lib\site-packages\docker\transport\npipesocket.py", line 54, in connect
    handle = win32file.CreateFile(
             ^^^^^^^^^^^^^^^^^^^^^
pywintypes.error: (2, 'CreateFile', 'Nie można odnaleźć określonego pliku.')

The above exception was the direct cause of the following exception:

Traceback (most recent call last):
  File "c:\Users\grabowmar\Desktop\ThesisAppsSvelte\z_interface_app\services.py", line 118, in _create_docker_client
    client = docker.DockerClient(base_url=docker_host, timeout=timeout)
             ^^^^^^^^^^^^^^^^^^^^^^^^^^^^^^^^^^^^^^^^^^^^^^^^^^^^^^^^^^
  File "C:\Users\grabowmar\Desktop\ThesisAppsSvelte\.venv\Lib\site-packages\docker\client.py", line 45, in __init__
    self.api = APIClient(*args, **kwargs)
               ^^^^^^^^^^^^^^^^^^^^^^^^^^
  File "C:\Users\grabowmar\Desktop\ThesisAppsSvelte\.venv\Lib\site-packages\docker\api\client.py", line 207, in __init__
    self._version = self._retrieve_server_version()
                    ^^^^^^^^^^^^^^^^^^^^^^^^^^^^^^^
  File "C:\Users\grabowmar\Desktop\ThesisAppsSvelte\.venv\Lib\site-packages\docker\api\client.py", line 230, in _retrieve_server_version
    raise DockerException(
docker.errors.DockerException: Error while fetching server API version: (2, 'CreateFile', 'Nie można odnaleźć określonego pliku.')
2025-05-03 13:17:58 [ERROR] [-] docker.docker._create_docker_client:124 - Docker client creation or connection failed: Error while fetching server API version: (2, 'CreateFile', 'Nie można odnaleźć określonego pliku.')
Traceback (most recent call last):
  File "C:\Users\grabowmar\Desktop\ThesisAppsSvelte\.venv\Lib\site-packages\docker\api\client.py", line 223, in _retrieve_server_version
    return self.version(api_version=False)["ApiVersion"]
           ^^^^^^^^^^^^^^^^^^^^^^^^^^^^^^^
  File "C:\Users\grabowmar\Desktop\ThesisAppsSvelte\.venv\Lib\site-packages\docker\api\daemon.py", line 181, in version
    return self._result(self._get(url), json=True)
                        ^^^^^^^^^^^^^^
  File "C:\Users\grabowmar\Desktop\ThesisAppsSvelte\.venv\Lib\site-packages\docker\utils\decorators.py", line 44, in inner
    return f(self, *args, **kwargs)
           ^^^^^^^^^^^^^^^^^^^^^^^^
  File "C:\Users\grabowmar\Desktop\ThesisAppsSvelte\.venv\Lib\site-packages\docker\api\client.py", line 246, in _get
    return self.get(url, **self._set_request_timeout(kwargs))
           ^^^^^^^^^^^^^^^^^^^^^^^^^^^^^^^^^^^^^^^^^^^^^^^^^^
  File "C:\Users\grabowmar\Desktop\ThesisAppsSvelte\.venv\Lib\site-packages\requests\sessions.py", line 602, in get
    return self.request("GET", url, **kwargs)
           ^^^^^^^^^^^^^^^^^^^^^^^^^^^^^^^^^^
  File "C:\Users\grabowmar\Desktop\ThesisAppsSvelte\.venv\Lib\site-packages\requests\sessions.py", line 589, in request
    resp = self.send(prep, **send_kwargs)
           ^^^^^^^^^^^^^^^^^^^^^^^^^^^^^^
  File "C:\Users\grabowmar\Desktop\ThesisAppsSvelte\.venv\Lib\site-packages\requests\sessions.py", line 703, in send
    r = adapter.send(request, **kwargs)
        ^^^^^^^^^^^^^^^^^^^^^^^^^^^^^^^
  File "C:\Users\grabowmar\Desktop\ThesisAppsSvelte\.venv\Lib\site-packages\requests\adapters.py", line 667, in send
    resp = conn.urlopen(
           ^^^^^^^^^^^^^
  File "C:\Users\grabowmar\Desktop\ThesisAppsSvelte\.venv\Lib\site-packages\urllib3\connectionpool.py", line 787, in urlopen
    response = self._make_request(
               ^^^^^^^^^^^^^^^^^^^
  File "C:\Users\grabowmar\Desktop\ThesisAppsSvelte\.venv\Lib\site-packages\urllib3\connectionpool.py", line 493, in _make_request
    conn.request(
  File "C:\Users\grabowmar\Desktop\ThesisAppsSvelte\.venv\Lib\site-packages\urllib3\connection.py", line 445, in request
    self.endheaders()
  File "c:\Users\grabowmar\AppData\Local\Programs\Python\Python312\Lib\http\client.py", line 1331, in endheaders
    self._send_output(message_body, encode_chunked=encode_chunked)
  File "c:\Users\grabowmar\AppData\Local\Programs\Python\Python312\Lib\http\client.py", line 1091, in _send_output
    self.send(msg)
  File "c:\Users\grabowmar\AppData\Local\Programs\Python\Python312\Lib\http\client.py", line 1035, in send
    self.connect()
  File "C:\Users\grabowmar\Desktop\ThesisAppsSvelte\.venv\Lib\site-packages\docker\transport\npipeconn.py", line 25, in connect
    sock.connect(self.npipe_path)
  File "C:\Users\grabowmar\Desktop\ThesisAppsSvelte\.venv\Lib\site-packages\docker\transport\npipesocket.py", line 25, in wrapped
    return f(self, *args, **kwargs)
           ^^^^^^^^^^^^^^^^^^^^^^^^
  File "C:\Users\grabowmar\Desktop\ThesisAppsSvelte\.venv\Lib\site-packages\docker\transport\npipesocket.py", line 76, in connect
    raise e
  File "C:\Users\grabowmar\Desktop\ThesisAppsSvelte\.venv\Lib\site-packages\docker\transport\npipesocket.py", line 54, in connect
    handle = win32file.CreateFile(
             ^^^^^^^^^^^^^^^^^^^^^
pywintypes.error: (2, 'CreateFile', 'Nie można odnaleźć określonego pliku.')

The above exception was the direct cause of the following exception:

Traceback (most recent call last):
  File "c:\Users\grabowmar\Desktop\ThesisAppsSvelte\z_interface_app\services.py", line 118, in _create_docker_client
    client = docker.DockerClient(base_url=docker_host, timeout=timeout)
             ^^^^^^^^^^^^^^^^^^^^^^^^^^^^^^^^^^^^^^^^^^^^^^^^^^^^^^^^^^
  File "C:\Users\grabowmar\Desktop\ThesisAppsSvelte\.venv\Lib\site-packages\docker\client.py", line 45, in __init__
    self.api = APIClient(*args, **kwargs)
               ^^^^^^^^^^^^^^^^^^^^^^^^^^
  File "C:\Users\grabowmar\Desktop\ThesisAppsSvelte\.venv\Lib\site-packages\docker\api\client.py", line 207, in __init__
    self._version = self._retrieve_server_version()
                    ^^^^^^^^^^^^^^^^^^^^^^^^^^^^^^^
  File "C:\Users\grabowmar\Desktop\ThesisAppsSvelte\.venv\Lib\site-packages\docker\api\client.py", line 230, in _retrieve_server_version
    raise DockerException(
docker.errors.DockerException: Error while fetching server API version: (2, 'CreateFile', 'Nie można odnaleźć określonego pliku.')
2025-05-03 13:36:22 [ERROR] [-] docker.docker._create_docker_client:124 - Docker client creation or connection failed: Error while fetching server API version: (2, 'CreateFile', 'Nie można odnaleźć określonego pliku.')
Traceback (most recent call last):
  File "C:\Users\grabowmar\Desktop\ThesisAppsSvelte\.venv\Lib\site-packages\docker\api\client.py", line 223, in _retrieve_server_version
    return self.version(api_version=False)["ApiVersion"]
           ^^^^^^^^^^^^^^^^^^^^^^^^^^^^^^^
  File "C:\Users\grabowmar\Desktop\ThesisAppsSvelte\.venv\Lib\site-packages\docker\api\daemon.py", line 181, in version
    return self._result(self._get(url), json=True)
                        ^^^^^^^^^^^^^^
  File "C:\Users\grabowmar\Desktop\ThesisAppsSvelte\.venv\Lib\site-packages\docker\utils\decorators.py", line 44, in inner
    return f(self, *args, **kwargs)
           ^^^^^^^^^^^^^^^^^^^^^^^^
  File "C:\Users\grabowmar\Desktop\ThesisAppsSvelte\.venv\Lib\site-packages\docker\api\client.py", line 246, in _get
    return self.get(url, **self._set_request_timeout(kwargs))
           ^^^^^^^^^^^^^^^^^^^^^^^^^^^^^^^^^^^^^^^^^^^^^^^^^^
  File "C:\Users\grabowmar\Desktop\ThesisAppsSvelte\.venv\Lib\site-packages\requests\sessions.py", line 602, in get
    return self.request("GET", url, **kwargs)
           ^^^^^^^^^^^^^^^^^^^^^^^^^^^^^^^^^^
  File "C:\Users\grabowmar\Desktop\ThesisAppsSvelte\.venv\Lib\site-packages\requests\sessions.py", line 589, in request
    resp = self.send(prep, **send_kwargs)
           ^^^^^^^^^^^^^^^^^^^^^^^^^^^^^^
  File "C:\Users\grabowmar\Desktop\ThesisAppsSvelte\.venv\Lib\site-packages\requests\sessions.py", line 703, in send
    r = adapter.send(request, **kwargs)
        ^^^^^^^^^^^^^^^^^^^^^^^^^^^^^^^
  File "C:\Users\grabowmar\Desktop\ThesisAppsSvelte\.venv\Lib\site-packages\requests\adapters.py", line 667, in send
    resp = conn.urlopen(
           ^^^^^^^^^^^^^
  File "C:\Users\grabowmar\Desktop\ThesisAppsSvelte\.venv\Lib\site-packages\urllib3\connectionpool.py", line 787, in urlopen
    response = self._make_request(
               ^^^^^^^^^^^^^^^^^^^
  File "C:\Users\grabowmar\Desktop\ThesisAppsSvelte\.venv\Lib\site-packages\urllib3\connectionpool.py", line 493, in _make_request
    conn.request(
  File "C:\Users\grabowmar\Desktop\ThesisAppsSvelte\.venv\Lib\site-packages\urllib3\connection.py", line 445, in request
    self.endheaders()
  File "c:\Users\grabowmar\AppData\Local\Programs\Python\Python312\Lib\http\client.py", line 1331, in endheaders
    self._send_output(message_body, encode_chunked=encode_chunked)
  File "c:\Users\grabowmar\AppData\Local\Programs\Python\Python312\Lib\http\client.py", line 1091, in _send_output
    self.send(msg)
  File "c:\Users\grabowmar\AppData\Local\Programs\Python\Python312\Lib\http\client.py", line 1035, in send
    self.connect()
  File "C:\Users\grabowmar\Desktop\ThesisAppsSvelte\.venv\Lib\site-packages\docker\transport\npipeconn.py", line 25, in connect
    sock.connect(self.npipe_path)
  File "C:\Users\grabowmar\Desktop\ThesisAppsSvelte\.venv\Lib\site-packages\docker\transport\npipesocket.py", line 25, in wrapped
    return f(self, *args, **kwargs)
           ^^^^^^^^^^^^^^^^^^^^^^^^
  File "C:\Users\grabowmar\Desktop\ThesisAppsSvelte\.venv\Lib\site-packages\docker\transport\npipesocket.py", line 76, in connect
    raise e
  File "C:\Users\grabowmar\Desktop\ThesisAppsSvelte\.venv\Lib\site-packages\docker\transport\npipesocket.py", line 54, in connect
    handle = win32file.CreateFile(
             ^^^^^^^^^^^^^^^^^^^^^
pywintypes.error: (2, 'CreateFile', 'Nie można odnaleźć określonego pliku.')

The above exception was the direct cause of the following exception:

Traceback (most recent call last):
  File "c:\Users\grabowmar\Desktop\ThesisAppsSvelte\z_interface_app\services.py", line 118, in _create_docker_client
    client = docker.DockerClient(base_url=docker_host, timeout=timeout)
             ^^^^^^^^^^^^^^^^^^^^^^^^^^^^^^^^^^^^^^^^^^^^^^^^^^^^^^^^^^
  File "C:\Users\grabowmar\Desktop\ThesisAppsSvelte\.venv\Lib\site-packages\docker\client.py", line 45, in __init__
    self.api = APIClient(*args, **kwargs)
               ^^^^^^^^^^^^^^^^^^^^^^^^^^
  File "C:\Users\grabowmar\Desktop\ThesisAppsSvelte\.venv\Lib\site-packages\docker\api\client.py", line 207, in __init__
    self._version = self._retrieve_server_version()
                    ^^^^^^^^^^^^^^^^^^^^^^^^^^^^^^^
  File "C:\Users\grabowmar\Desktop\ThesisAppsSvelte\.venv\Lib\site-packages\docker\api\client.py", line 230, in _retrieve_server_version
    raise DockerException(
docker.errors.DockerException: Error while fetching server API version: (2, 'CreateFile', 'Nie można odnaleźć określonego pliku.')
2025-05-03 13:36:29 [ERROR] [-] docker.docker._create_docker_client:124 - Docker client creation or connection failed: Error while fetching server API version: (2, 'CreateFile', 'Nie można odnaleźć określonego pliku.')
Traceback (most recent call last):
  File "C:\Users\grabowmar\Desktop\ThesisAppsSvelte\.venv\Lib\site-packages\docker\api\client.py", line 223, in _retrieve_server_version
    return self.version(api_version=False)["ApiVersion"]
           ^^^^^^^^^^^^^^^^^^^^^^^^^^^^^^^
  File "C:\Users\grabowmar\Desktop\ThesisAppsSvelte\.venv\Lib\site-packages\docker\api\daemon.py", line 181, in version
    return self._result(self._get(url), json=True)
                        ^^^^^^^^^^^^^^
  File "C:\Users\grabowmar\Desktop\ThesisAppsSvelte\.venv\Lib\site-packages\docker\utils\decorators.py", line 44, in inner
    return f(self, *args, **kwargs)
           ^^^^^^^^^^^^^^^^^^^^^^^^
  File "C:\Users\grabowmar\Desktop\ThesisAppsSvelte\.venv\Lib\site-packages\docker\api\client.py", line 246, in _get
    return self.get(url, **self._set_request_timeout(kwargs))
           ^^^^^^^^^^^^^^^^^^^^^^^^^^^^^^^^^^^^^^^^^^^^^^^^^^
  File "C:\Users\grabowmar\Desktop\ThesisAppsSvelte\.venv\Lib\site-packages\requests\sessions.py", line 602, in get
    return self.request("GET", url, **kwargs)
           ^^^^^^^^^^^^^^^^^^^^^^^^^^^^^^^^^^
  File "C:\Users\grabowmar\Desktop\ThesisAppsSvelte\.venv\Lib\site-packages\requests\sessions.py", line 589, in request
    resp = self.send(prep, **send_kwargs)
           ^^^^^^^^^^^^^^^^^^^^^^^^^^^^^^
  File "C:\Users\grabowmar\Desktop\ThesisAppsSvelte\.venv\Lib\site-packages\requests\sessions.py", line 703, in send
    r = adapter.send(request, **kwargs)
        ^^^^^^^^^^^^^^^^^^^^^^^^^^^^^^^
  File "C:\Users\grabowmar\Desktop\ThesisAppsSvelte\.venv\Lib\site-packages\requests\adapters.py", line 667, in send
    resp = conn.urlopen(
           ^^^^^^^^^^^^^
  File "C:\Users\grabowmar\Desktop\ThesisAppsSvelte\.venv\Lib\site-packages\urllib3\connectionpool.py", line 787, in urlopen
    response = self._make_request(
               ^^^^^^^^^^^^^^^^^^^
  File "C:\Users\grabowmar\Desktop\ThesisAppsSvelte\.venv\Lib\site-packages\urllib3\connectionpool.py", line 493, in _make_request
    conn.request(
  File "C:\Users\grabowmar\Desktop\ThesisAppsSvelte\.venv\Lib\site-packages\urllib3\connection.py", line 445, in request
    self.endheaders()
  File "c:\Users\grabowmar\AppData\Local\Programs\Python\Python312\Lib\http\client.py", line 1331, in endheaders
    self._send_output(message_body, encode_chunked=encode_chunked)
  File "c:\Users\grabowmar\AppData\Local\Programs\Python\Python312\Lib\http\client.py", line 1091, in _send_output
    self.send(msg)
  File "c:\Users\grabowmar\AppData\Local\Programs\Python\Python312\Lib\http\client.py", line 1035, in send
    self.connect()
  File "C:\Users\grabowmar\Desktop\ThesisAppsSvelte\.venv\Lib\site-packages\docker\transport\npipeconn.py", line 25, in connect
    sock.connect(self.npipe_path)
  File "C:\Users\grabowmar\Desktop\ThesisAppsSvelte\.venv\Lib\site-packages\docker\transport\npipesocket.py", line 25, in wrapped
    return f(self, *args, **kwargs)
           ^^^^^^^^^^^^^^^^^^^^^^^^
  File "C:\Users\grabowmar\Desktop\ThesisAppsSvelte\.venv\Lib\site-packages\docker\transport\npipesocket.py", line 76, in connect
    raise e
  File "C:\Users\grabowmar\Desktop\ThesisAppsSvelte\.venv\Lib\site-packages\docker\transport\npipesocket.py", line 54, in connect
    handle = win32file.CreateFile(
             ^^^^^^^^^^^^^^^^^^^^^
pywintypes.error: (2, 'CreateFile', 'Nie można odnaleźć określonego pliku.')

The above exception was the direct cause of the following exception:

Traceback (most recent call last):
  File "c:\Users\grabowmar\Desktop\ThesisAppsSvelte\z_interface_app\services.py", line 118, in _create_docker_client
    client = docker.DockerClient(base_url=docker_host, timeout=timeout)
             ^^^^^^^^^^^^^^^^^^^^^^^^^^^^^^^^^^^^^^^^^^^^^^^^^^^^^^^^^^
  File "C:\Users\grabowmar\Desktop\ThesisAppsSvelte\.venv\Lib\site-packages\docker\client.py", line 45, in __init__
    self.api = APIClient(*args, **kwargs)
               ^^^^^^^^^^^^^^^^^^^^^^^^^^
  File "C:\Users\grabowmar\Desktop\ThesisAppsSvelte\.venv\Lib\site-packages\docker\api\client.py", line 207, in __init__
    self._version = self._retrieve_server_version()
                    ^^^^^^^^^^^^^^^^^^^^^^^^^^^^^^^
  File "C:\Users\grabowmar\Desktop\ThesisAppsSvelte\.venv\Lib\site-packages\docker\api\client.py", line 230, in _retrieve_server_version
    raise DockerException(
docker.errors.DockerException: Error while fetching server API version: (2, 'CreateFile', 'Nie można odnaleźć określonego pliku.')
2025-05-03 13:36:31 [ERROR] [-] docker.docker._create_docker_client:124 - Docker client creation or connection failed: Error while fetching server API version: (2, 'CreateFile', 'Nie można odnaleźć określonego pliku.')
Traceback (most recent call last):
  File "C:\Users\grabowmar\Desktop\ThesisAppsSvelte\.venv\Lib\site-packages\docker\api\client.py", line 223, in _retrieve_server_version
    return self.version(api_version=False)["ApiVersion"]
           ^^^^^^^^^^^^^^^^^^^^^^^^^^^^^^^
  File "C:\Users\grabowmar\Desktop\ThesisAppsSvelte\.venv\Lib\site-packages\docker\api\daemon.py", line 181, in version
    return self._result(self._get(url), json=True)
                        ^^^^^^^^^^^^^^
  File "C:\Users\grabowmar\Desktop\ThesisAppsSvelte\.venv\Lib\site-packages\docker\utils\decorators.py", line 44, in inner
    return f(self, *args, **kwargs)
           ^^^^^^^^^^^^^^^^^^^^^^^^
  File "C:\Users\grabowmar\Desktop\ThesisAppsSvelte\.venv\Lib\site-packages\docker\api\client.py", line 246, in _get
    return self.get(url, **self._set_request_timeout(kwargs))
           ^^^^^^^^^^^^^^^^^^^^^^^^^^^^^^^^^^^^^^^^^^^^^^^^^^
  File "C:\Users\grabowmar\Desktop\ThesisAppsSvelte\.venv\Lib\site-packages\requests\sessions.py", line 602, in get
    return self.request("GET", url, **kwargs)
           ^^^^^^^^^^^^^^^^^^^^^^^^^^^^^^^^^^
  File "C:\Users\grabowmar\Desktop\ThesisAppsSvelte\.venv\Lib\site-packages\requests\sessions.py", line 589, in request
    resp = self.send(prep, **send_kwargs)
           ^^^^^^^^^^^^^^^^^^^^^^^^^^^^^^
  File "C:\Users\grabowmar\Desktop\ThesisAppsSvelte\.venv\Lib\site-packages\requests\sessions.py", line 703, in send
    r = adapter.send(request, **kwargs)
        ^^^^^^^^^^^^^^^^^^^^^^^^^^^^^^^
  File "C:\Users\grabowmar\Desktop\ThesisAppsSvelte\.venv\Lib\site-packages\requests\adapters.py", line 667, in send
    resp = conn.urlopen(
           ^^^^^^^^^^^^^
  File "C:\Users\grabowmar\Desktop\ThesisAppsSvelte\.venv\Lib\site-packages\urllib3\connectionpool.py", line 787, in urlopen
    response = self._make_request(
               ^^^^^^^^^^^^^^^^^^^
  File "C:\Users\grabowmar\Desktop\ThesisAppsSvelte\.venv\Lib\site-packages\urllib3\connectionpool.py", line 493, in _make_request
    conn.request(
  File "C:\Users\grabowmar\Desktop\ThesisAppsSvelte\.venv\Lib\site-packages\urllib3\connection.py", line 445, in request
    self.endheaders()
  File "c:\Users\grabowmar\AppData\Local\Programs\Python\Python312\Lib\http\client.py", line 1331, in endheaders
    self._send_output(message_body, encode_chunked=encode_chunked)
  File "c:\Users\grabowmar\AppData\Local\Programs\Python\Python312\Lib\http\client.py", line 1091, in _send_output
    self.send(msg)
  File "c:\Users\grabowmar\AppData\Local\Programs\Python\Python312\Lib\http\client.py", line 1035, in send
    self.connect()
  File "C:\Users\grabowmar\Desktop\ThesisAppsSvelte\.venv\Lib\site-packages\docker\transport\npipeconn.py", line 25, in connect
    sock.connect(self.npipe_path)
  File "C:\Users\grabowmar\Desktop\ThesisAppsSvelte\.venv\Lib\site-packages\docker\transport\npipesocket.py", line 25, in wrapped
    return f(self, *args, **kwargs)
           ^^^^^^^^^^^^^^^^^^^^^^^^
  File "C:\Users\grabowmar\Desktop\ThesisAppsSvelte\.venv\Lib\site-packages\docker\transport\npipesocket.py", line 76, in connect
    raise e
  File "C:\Users\grabowmar\Desktop\ThesisAppsSvelte\.venv\Lib\site-packages\docker\transport\npipesocket.py", line 54, in connect
    handle = win32file.CreateFile(
             ^^^^^^^^^^^^^^^^^^^^^
pywintypes.error: (2, 'CreateFile', 'Nie można odnaleźć określonego pliku.')

The above exception was the direct cause of the following exception:

Traceback (most recent call last):
  File "c:\Users\grabowmar\Desktop\ThesisAppsSvelte\z_interface_app\services.py", line 118, in _create_docker_client
    client = docker.DockerClient(base_url=docker_host, timeout=timeout)
             ^^^^^^^^^^^^^^^^^^^^^^^^^^^^^^^^^^^^^^^^^^^^^^^^^^^^^^^^^^
  File "C:\Users\grabowmar\Desktop\ThesisAppsSvelte\.venv\Lib\site-packages\docker\client.py", line 45, in __init__
    self.api = APIClient(*args, **kwargs)
               ^^^^^^^^^^^^^^^^^^^^^^^^^^
  File "C:\Users\grabowmar\Desktop\ThesisAppsSvelte\.venv\Lib\site-packages\docker\api\client.py", line 207, in __init__
    self._version = self._retrieve_server_version()
                    ^^^^^^^^^^^^^^^^^^^^^^^^^^^^^^^
  File "C:\Users\grabowmar\Desktop\ThesisAppsSvelte\.venv\Lib\site-packages\docker\api\client.py", line 230, in _retrieve_server_version
    raise DockerException(
docker.errors.DockerException: Error while fetching server API version: (2, 'CreateFile', 'Nie można odnaleźć określonego pliku.')
